Workbook
Name TotalFreight: 'Import Data Entry'!$B$18
Name EntryNumber: 'Import Data Entry'!$B$3
Name ValidationStatus: 'Import Data Entry'!$B$73

Sheet Import Data Entry
A1: DIE CO., INC. - IMPORT FREIGHT CALCULATOR
A2: Entry Summary Data
A3: Entry #: | B3: 2026-001-ABC
A4: Entry Date: | B4: 46028
A5: Vessel: | B5: MV PACIFIC TRADER
A6: Invoice #: | B6: INV-2026-001
A8: Total Duty (Box 37): | B8: 5000 | C8: From CBP Entry Summary
A9: Customs Entry Fee: | B9: 250
A10: ISF - Security Filing: | B10: 150
A11: Ocean Freight: | B11: 8500
A12: Terminal Handling/Services: | B12: 1200
A13: Cartage & Services: | B13: 850
A14: Other Fees: | B14: 300
A16: Total Freight Invoice: | B16: =SUM(B9:B14) | C16: From Freight Expediters Invoice
A18: FREIGHT DIFFERENTIAL TO ALLOCATE: | B18: =B16-B8 | C18: Amount to distribute across parts
A20: Part # | B20: Description | C20: Quantity | D20: Net Weight (KG) | E20: # of Skids | F20: Weight per Skid | G20: Total Part Weight | H20: Weight % | I20: Allocated Freight
A21: PN-12345 | B21: Widget Assembly Type A | C21: 5000 | D21: 2.5 | E21: 10 | F21: =IF(E21>0, D21*C21/E21, 0) | G21: =C21*D21 | H21: =IF($G$71>0, G21/$G$71, 0) | I21: =H21*$B$18
A22: PN-67890 | B22: Widget Assembly Type B | C22: 3000 | D22: 3.2 | E22: 8 | F22: =IF(E22>0, D22*C22/E22, 0) | G22: =C22*D22 | H22: =IF($G$71>0, G22/$G$71, 0) | I22: =H22*$B$18
A23: PN-24680 | B23: Widget Assembly Type C | C23: 7500 | D23: 1.8 | E23: 15 | F23: =IF(E23>0, D23*C23/E23, 0) | G23: =C23*D23 | H23: =IF($G$71>0, G23/$G$71, 0) | I23: =H23*$B$18
F24: =IF(E24>0, D24*C24/E24, 0) | G24: =C24*D24 | H24: =IF($G$71>0, G24/$G$71, 0) | I24: =H24*$B$18
F25: =IF(E25>0, D25*C25/E25, 0) | G25: =C25*D25 | H25: =IF($G$71>0, G25/$G$71, 0) | I25: =H25*$B$18
F26: =IF(E26>0, D26*C26/E26, 0) | G26: =C26*D26 | H26: =IF($G$71>0, G26/$G$71, 0) | I26: =H26*$B$18
F27: =IF(E27>0, D27*C27/E27, 0) | G27: =C27*D27 | H27: =IF($G$71>0, G27/$G$71, 0) | I27: =H27*$B$18
F28: =IF(E28>0, D28*C28/E28, 0) | G28: =C28*D28 | H28: =IF($G$71>0, G28/$G$71, 0) | I28: =H28*$B$18
F29: =IF(E29>0, D29*C29/E29, 0) | G29: =C29*D29 | H29: =IF($G$71>0, G29/$G$71, 0) | I29: =H29*$B$18
F30: =IF(E30>0, D30*C30/E30, 0) | G30: =C30*D30 | H30: =IF($G$71>0, G30/$G$71, 0) | I30: =H30*$B$18
F31: =IF(E31>0, D31*C31/E31, 0) | G31: =C31*D31 | H31: =IF($G$71>0, G31/$G$71, 0) | I31: =H31*$B$18
F32: =IF(E32>0, D32*C32/E32, 0) | G32: =C32*D32 | H32: =IF($G$71>0, G32/$G$71, 0) | I32: =H32*$B$18
F33: =IF(E33>0, D33*C33/E33, 0) | G33: =C33*D33 | H33: =IF($G$71>0, G33/$G$71, 0) | I33: =H33*$B$18
F34: =IF(E34>0, D34*C34/E34, 0) | G34: =C34*D34 | H34: =IF($G$71>0, G34/$G$71, 0) | I34: =H34*$B$18
F35: =IF(E35>0, D35*C35/E35, 0) | G35: =C35*D35 | H35: =IF($G$71>0, G35/$G$71, 0) | I35: =H35*$B$18
... F70: =IF(E70>0, D70*C70/E70, 0) | G70: =C70*D70 | H70: =IF($G$71>0, G70/$G$71, 0) | I70: =H70*$B$18
A71: TOTALS: | C71: =SUM(C21:C70) | E71: =SUM(E21:E70) | G71: =SUM(G21:G70) | H71: =SUM(H21:H70) | I71: =SUM(I21:I70)
A73: Validation Check: | B73: =IF(ABS(I71-B18)<0.01, "✓ PASS", "✗ FAIL - Allocation Error")
A75: INSTRUCTIONS: Enter CBP Entry Summary data in Section A. Enter Freight Expediters invoice total. Enter part details starting row 21. Freight will auto-allocate by weight percentage.

Sheet Freight Calculator
A1: FREIGHT COST ANALYSIS
A2: Entry #: | B2: ='Import Data Entry'!B3 | D2: Vessel: | E2: ='Import Data Entry'!B5 | G2: Total Freight: | H2: ='Import Data Entry'!B18
A4: Part # | B4: Description | C4: Quantity (M) | D4: Net Weight (KG) | E4: Allocated Freight | F4: Cost per M | G4: Cost per Unit | H4: Cost per KG | I4: DRM Code | J4: Notes
A5: ='Import Data Entry'!A21 | B5: ='Import Data Entry'!B21 | C5: ='Import Data Entry'!C21/1000 | D5: ='Import Data Entry'!D21 | E5: ='Import Data Entry'!I21 | F5: =IF(C5>0, E5/C5, 0) | G5: =IF(C5>0, E5/(C5*1000), 0) | H5: =IF(D5>0, E5/(D5*C5*1000), 0) | I5: DRM-A
A6: ='Import Data Entry'!A22 | B6: ='Import Data Entry'!B22 | C6: ='Import Data Entry'!C22/1000 | D6: ='Import Data Entry'!D22 | E6: ='Import Data Entry'!I22 | F6: =IF(C6>0, E6/C6, 0) | G6: =IF(C6>0, E6/(C6*1000), 0) | H6: =IF(D6>0, E6/(D6*C6*1000), 0) | I6: DRM-B
A7: ='Import Data Entry'!A23 | B7: ='Import Data Entry'!B23 | C7: ='Import Data Entry'!C23/1000 | D7: ='Import Data Entry'!D23 | E7: ='Import Data Entry'!I23 | F7: =IF(C7>0, E7/C7, 0) | G7: =IF(C7>0, E7/(C7*1000), 0) | H7: =IF(D7>0, E7/(D7*C7*1000), 0) | I7: DRM-C
A8: ='Import Data Entry'!A24 | B8: ='Import Data Entry'!B24 | C8: ='Import Data Entry'!C24/1000 | D8: ='Import Data Entry'!D24 | E8: ='Import Data Entry'!I24 | F8: =IF(C8>0, E8/C8, 0) | G8: =IF(C8>0, E8/(C8*1000), 0) | H8: =IF(D8>0, E8/(D8*C8*1000), 0)
A9: ='Import Data Entry'!A25 | B9: ='Import Data Entry'!B25 | C9: ='Import Data Entry'!C25/1000 | D9: ='Import Data Entry'!D25 | E9: ='Import Data Entry'!I25 | F9: =IF(C9>0, E9/C9, 0) | G9: =IF(C9>0, E9/(C9*1000), 0) | H9: =IF(D9>0, E9/(D9*C9*1000), 0)
A10: ='Import Data Entry'!A26 | B10: ='Import Data Entry'!B26 | C10: ='Import Data Entry'!C26/1000 | D10: ='Import Data Entry'!D26 | E10: ='Import Data Entry'!I26 | F10: =IF(C10>0, E10/C10, 0) | G10: =IF(C10>0, E10/(C10*1000), 0) | H10: =IF(D10>0, E10/(D10*C10*1000), 0)
A11: ='Import Data Entry'!A27 | B11: ='Import Data Entry'!B27 | C11: ='Import Data Entry'!C27/1000 | D11: ='Import Data Entry'!D27 | E11: ='Import Data Entry'!I27 | F11: =IF(C11>0, E11/C11, 0) | G11: =IF(C11>0, E11/(C11*1000), 0) | H11: =IF(D11>0, E11/(D11*C11*1000), 0)
A12: ='Import Data Entry'!A28 | B12: ='Import Data Entry'!B28 | C12: ='Import Data Entry'!C28/1000 | D12: ='Import Data Entry'!D28 | E12: ='Import Data Entry'!I28 | F12: =IF(C12>0, E12/C12, 0) | G12: =IF(C12>0, E12/(C12*1000), 0) | H12: =IF(D12>0, E12/(D12*C12*1000), 0)
A13: ='Import Data Entry'!A29 | B13: ='Import Data Entry'!B29 | C13: ='Import Data Entry'!C29/1000 | D13: ='Import Data Entry'!D29 | E13: ='Import Data Entry'!I29 | F13: =IF(C13>0, E13/C13, 0) | G13: =IF(C13>0, E13/(C13*1000), 0) | H13: =IF(D13>0, E13/(D13*C13*1000), 0)
A14: ='Import Data Entry'!A30 | B14: ='Import Data Entry'!B30 | C14: ='Import Data Entry'!C30/1000 | D14: ='Import Data Entry'!D30 | E14: ='Import Data Entry'!I30 | F14: =IF(C14>0, E14/C14, 0) | G14: =IF(C14>0, E14/(C14*1000), 0) | H14: =IF(D14>0, E14/(D14*C14*1000), 0)
A15: ='Import Data Entry'!A31 | B15: ='Import Data Entry'!B31 | C15: ='Import Data Entry'!C31/1000 | D15: ='Import Data Entry'!D31 | E15: ='Import Data Entry'!I31 | F15: =IF(C15>0, E15/C15, 0) | G15: =IF(C15>0, E15/(C15*1000), 0) | H15: =IF(D15>0, E15/(D15*C15*1000), 0)
A16: ='Import Data Entry'!A32 | B16: ='Import Data Entry'!B32 | C16: ='Import Data Entry'!C32/1000 | D16: ='Import Data Entry'!D32 | E16: ='Import Data Entry'!I32 | F16: =IF(C16>0, E16/C16, 0) | G16: =IF(C16>0, E16/(C16*1000), 0) | H16: =IF(D16>0, E16/(D16*C16*1000), 0)
A17: ='Import Data Entry'!A33 | B17: ='Import Data Entry'!B33 | C17: ='Import Data Entry'!C33/1000 | D17: ='Import Data Entry'!D33 | E17: ='Import Data Entry'!I33 | F17: =IF(C17>0, E17/C17, 0) | G17: =IF(C17>0, E17/(C17*1000), 0) | H17: =IF(D17>0, E17/(D17*C17*1000), 0)
A18: ='Import Data Entry'!A34 | B18: ='Import Data Entry'!B34 | C18: ='Import Data Entry'!C34/1000 | D18: ='Import Data Entry'!D34 | E18: ='Import Data Entry'!I34 | F18: =IF(C18>0, E18/C18, 0) | G18: =IF(C18>0, E18/(C18*1000), 0) | H18: =IF(D18>0, E18/(D18*C18*1000), 0)
A19: ='Import Data Entry'!A35 | B19: ='Import Data Entry'!B35 | C19: ='Import Data Entry'!C35/1000 | D19: ='Import Data Entry'!D35 | E19: ='Import Data Entry'!I35 | F19: =IF(C19>0, E19/C19, 0) | G19: =IF(C19>0, E19/(C19*1000), 0) | H19: =IF(D19>0, E19/(D19*C19*1000), 0)
... A54: ='Import Data Entry'!A70 | B54: ='Import Data Entry'!B70 | C54: ='Import Data Entry'!C70/1000 | D54: ='Import Data Entry'!D70 | E54: ='Import Data Entry'!I70 | F54: =IF(C54>0, E54/C54, 0) | G54: =IF(C54>0, E54/(C54*1000), 0) | H54: =IF(D54>0, E54/(D54*C54*1000), 0)
A56: TOTALS: | E56: =SUM(E5:E54)

Sheet ERP Upload
A1: ERP IMPORT TEMPLATE - DO NOT MODIFY HEADERS
A2: Part_Number | B2: DRM_Code | C2: Freight_Cost_Per_M | D2: Freight_Cost_Per_Unit | E2: Entry_Number
A3: ='Freight Calculator'!A5 | B3: ='Freight Calculator'!I5 | C3: =ROUND('Freight Calculator'!F5,4) | D3: =ROUND('Freight Calculator'!G5,6) | E3: ='Import Data Entry'!B3
A4: ='Freight Calculator'!A6 | B4: ='Freight Calculator'!I6 | C4: =ROUND('Freight Calculator'!F6,4) | D4: =ROUND('Freight Calculator'!G6,6) | E4: ='Import Data Entry'!B3
A5: ='Freight Calculator'!A7 | B5: ='Freight Calculator'!I7 | C5: =ROUND('Freight Calculator'!F7,4) | D5: =ROUND('Freight Calculator'!G7,6) | E5: ='Import Data Entry'!B3
A6: ='Freight Calculator'!A8 | B6: ='Freight Calculator'!I8 | C6: =ROUND('Freight Calculator'!F8,4) | D6: =ROUND('Freight Calculator'!G8,6) | E6: ='Import Data Entry'!B3
A7: ='Freight Calculator'!A9 | B7: ='Freight Calculator'!I9 | C7: =ROUND('Freight Calculator'!F9,4) | D7: =ROUND('Freight Calculator'!G9,6) | E7: ='Import Data Entry'!B3
A8: ='Freight Calculator'!A10 | B8: ='Freight Calculator'!I10 | C8: =ROUND('Freight Calculator'!F10,4) | D8: =ROUND('Freight Calculator'!G10,6) | E8: ='Import Data Entry'!B3
A9: ='Freight Calculator'!A11 | B9: ='Freight Calculator'!I11 | C9: =ROUND('Freight Calculator'!F11,4) | D9: =ROUND('Freight Calculator'!G11,6) | E9: ='Import Data Entry'!B3
A10: ='Freight Calculator'!A12 | B10: ='Freight Calculator'!I12 | C10: =ROUND('Freight Calculator'!F12,4) | D10: =ROUND('Freight Calculator'!G12,6) | E10: ='Import Data Entry'!B3
A11: ='Freight Calculator'!A13 | B11: ='Freight Calculator'!I13 | C11: =ROUND('Freight Calculator'!F13,4) | D11: =ROUND('Freight Calculator'!G13,6) | E11: ='Import Data Entry'!B3
A12: ='Freight Calculator'!A14 | B12: ='Freight Calculator'!I14 | C12: =ROUND('Freight Calculator'!F14,4) | D12: =ROUND('Freight Calculator'!G14,6) | E12: ='Import Data Entry'!B3
A13: ='Freight Calculator'!A15 | B13: ='Freight Calculator'!I15 | C13: =ROUND('Freight Calculator'!F15,4) | D13: =ROUND('Freight Calculator'!G15,6) | E13: ='Import Data Entry'!B3
A14: ='Freight Calculator'!A16 | B14: ='Freight Calculator'!I16 | C14: =ROUND('Freight Calculator'!F16,4) | D14: =ROUND('Freight Calculator'!G16,6) | E14: ='Import Data Entry'!B3
A15: ='Freight Calculator'!A17 | B15: ='Freight Calculator'!I17 | C15: =ROUND('Freight Calculator'!F17,4) | D15: =ROUND('Freight Calculator'!G17,6) | E15: ='Import Data Entry'!B3
A16: ='Freight Calculator'!A18 | B16: ='Freight Calculator'!I18 | C16: =ROUND('Freight Calculator'!F18,4) | D16: =ROUND('Freight Calculator'!G18,6) | E16: ='Import Data Entry'!B3
A17: ='Freight Calculator'!A19 | B17: ='Freight Calculator'!I19 | C17: =ROUND('Freight Calculator'!F19,4) | D17: =ROUND('Freight Calculator'!G19,6) | E17: ='Import Data Entry'!B3
A18: ='Freight Calculator'!A20 | B18: ='Freight Calculator'!I20 | C18: =ROUND('Freight Calculator'!F20,4) | D18: =ROUND('Freight Calculator'!G20,6) | E18: ='Import Data Entry'!B3
A19: ='Freight Calculator'!A21 | B19: ='Freight Calculator'!I21 | C19: =ROUND('Freight Calculator'!F21,4) | D19: =ROUND('Freight Calculator'!G21,6) | E19: ='Import Data Entry'!B3
A20: ='Freight Calculator'!A22 | B20: ='Freight Calculator'!I22 | C20: =ROUND('Freight Calculator'!F22,4) | D20: =ROUND('Freight Calculator'!G22,6) | E20: ='Import Data Entry'!B3
A21: ='Freight Calculator'!A23 | B21: ='Freight Calculator'!I23 | C21: =ROUND('Freight Calculator'!F23,4) | D21: =ROUND('Freight Calculator'!G23,6) | E21: ='Import Data Entry'!B3
A22: ='Freight Calculator'!A24 | B22: ='Freight Calculator'!I24 | C22: =ROUND('Freight Calculator'!F24,4) | D22: =ROUND('Freight Calculator'!G24,6) | E22: ='Import Data Entry'!B3
A23: ='Freight Calculator'!A25 | B23: ='Freight Calculator'!I25 | C23: =ROUND('Freight Calculator'!F25,4) | D23: =ROUND('Freight Calculator'!G25,6) | E23: ='Import Data Entry'!B3
A24: ='Freight Calculator'!A26 | B24: ='Freight Calculator'!I26 | C24: =ROUND('Freight Calculator'!F26,4) | D24: =ROUND('Freight Calculator'!G26,6) | E24: ='Import Data Entry'!B3
A25: ='Freight Calculator'!A27 | B25: ='Freight Calculator'!I27 | C25: =ROUND('Freight Calculator'!F27,4) | D25: =ROUND('Freight Calculator'!G27,6) | E25: ='Import Data Entry'!B3
A26: ='Freight Calculator'!A28 | B26: ='Freight Calculator'!I28 | C26: =ROUND('Freight Calculator'!F28,4) | D26: =ROUND('Freight Calculator'!G28,6) | E26: ='Import Data Entry'!B3
A27: ='Freight Calculator'!A29 | B27: ='Freight Calculator'!I29 | C27: =ROUND('Freight Calculator'!F29,4) | D27: =ROUND('Freight Calculator'!G29,6) | E27: ='Import Data Entry'!B3
A28: ='Freight Calculator'!A30 | B28: ='Freight Calculator'!I30 | C28: =ROUND('Freight Calculator'!F30,4) | D28: =ROUND('Freight Calculator'!G30,6) | E28: ='Import Data Entry'!B3
A29: ='Freight Calculator'!A31 | B29: ='Freight Calculator'!I31 | C29: =ROUND('Freight Calculator'!F31,4) | D29: =ROUND('Freight Calculator'!G31,6) | E29: ='Import Data Entry'!B3
A30: ='Freight Calculator'!A32 | B30: ='Freight Calculator'!I32 | C30: =ROUND('Freight Calculator'!F32,4) | D30: =ROUND('Freight Calculator'!G32,6) | E30: ='Import Data Entry'!B3
A31: ='Freight Calculator'!A33 | B31: ='Freight Calculator'!I33 | C31: =ROUND('Freight Calculator'!F33,4) | D31: =ROUND('Freight Calculator'!G33,6) | E31: ='Import Data Entry'!B3
A32: ='Freight Calculator'!A34 | B32: ='Freight Calculator'!I34 | C32: =ROUND('Freight Calculator'!F34,4) | D32: =ROUND('Freight Calculator'!G34,6) | E32: ='Import Data Entry'!B3
A33: ='Freight Calculator'!A35 | B33: ='Freight Calculator'!I35 | C33: =ROUND('Freight Calculator'!F35,4) | D33: =ROUND('Freight Calculator'!G35,6) | E33: ='Import Data Entry'!B3
A34: ='Freight Calculator'!A36 | B34: ='Freight Calculator'!I36 | C34: =ROUND('Freight Calculator'!F36,4) | D34: =ROUND('Freight Calculator'!G36,6) | E34: ='Import Data Entry'!B3
A35: ='Freight Calculator'!A37 | B35: ='Freight Calculator'!I37 | C35: =ROUND('Freight Calculator'!F37,4) | D35: =ROUND('Freight Calculator'!G37,6) | E35: ='Import Data Entry'!B3
A36: ='Freight Calculator'!A38 | B36: ='Freight Calculator'!I38 | C36: =ROUND('Freight Calculator'!F38,4) | D36: =ROUND('Freight Calculator'!G38,6) | E36: ='Import Data Entry'!B3
A37: ='Freight Calculator'!A39 | B37: ='Freight Calculator'!I39 | C37: =ROUND('Freight Calculator'!F39,4) | D37: =ROUND('Freight Calculator'!G39,6) | E37: ='Import Data Entry'!B3
A38: ='Freight Calculator'!A40 | B38: ='Freight Calculator'!I40 | C38: =ROUND('Freight Calculator'!F40,4) | D38: =ROUND('Freight Calculator'!G40,6) | E38: ='Import Data Entry'!B3
A39: ='Freight Calculator'!A41 | B39: ='Freight Calculator'!I41 | C39: =ROUND('Freight Calculator'!F41,4) | D39: =ROUND('Freight Calculator'!G41,6) | E39: ='Import Data Entry'!B3
A40: ='Freight Calculator'!A42 | B40: ='Freight Calculator'!I42 | C40: =ROUND('Freight Calculator'!F42,4) | D40: =ROUND('Freight Calculator'!G42,6) | E40: ='Import Data Entry'!B3
...
