Workbook
Name NetFreight: 'Import Data Entry'!$B$13
Name ShipmentDate: 'Import Data Entry'!$B$6
Name VesselName: 'Import Data Entry'!$B$5
Name TotalSkids: 'Import Data Entry'!$B$11

Sheet Import Data Entry
A1: DIE CO. NUT FREIGHT - IMPORT DATA ENTRY
A3: STEP 1: Enter Customs & Freight Data
A4: Entry Number: | B4: AVZ-0154383-3
A5: Vessel Name: | B5: EVER EAGLE 192E
A6: Entry Date: | B6: 46008
A8: Total Duty (CBP Box 37): | B8: 10991.5
A9: Freight Invoice Total: | B9: 15382.36
A10: Shipment Weight (KGS): | B10: 7821 | C10: From BOL or customs doc
A11: Number of Skids: | B11: 13
A13: NET FREIGHT TO ALLOCATE: | B13: =B9-B8
A15: STEP 2: Paste Part Details Below
A16: Part # | B16: Net Weight (KG) | C16: QTY (M) | D16: # of Skids | E16: Status
A17: DCS-621 | B17: 7.25 | C17: 243 | D17: 2 | E17: =IF(AND(A17<>"",B17<>"",C17<>"",D17<>""),"✓","")
A18: DCS-623 | B18: 6.9 | C18: 252 | D18: 2 | E18: =IF(AND(A18<>"",B18<>"",C18<>"",D18<>""),"✓","")
A19: DCS-672 | B19: 15.4 | C19: 264.6 | D19: 3 | E19: =IF(AND(A19<>"",B19<>"",C19<>"",D19<>""),"✓","")
A20: DCS-929 | B20: 7.94 | C20: 1020.6 | D20: 6 | E20: =IF(AND(A20<>"",B20<>"",C20<>"",D20<>""),"✓","")
E21: =IF(AND(A21<>"",B21<>"",C21<>"",D21<>""),"✓","")
E22: =IF(AND(A22<>"",B22<>"",C22<>"",D22<>""),"✓","")
E23: =IF(AND(A23<>"",B23<>"",C23<>"",D23<>""),"✓","")
E24: =IF(AND(A24<>"",B24<>"",C24<>"",D24<>""),"✓","")
E25: =IF(AND(A25<>"",B25<>"",C25<>"",D25<>""),"✓","")
E26: =IF(AND(A26<>"",B26<>"",C26<>"",D26<>""),"✓","")
E27: =IF(AND(A27<>"",B27<>"",C27<>"",D27<>""),"✓","")
E28: =IF(AND(A28<>"",B28<>"",C28<>"",D28<>""),"✓","")
E29: =IF(AND(A29<>"",B29<>"",C29<>"",D29<>""),"✓","")
E30: =IF(AND(A30<>"",B30<>"",C30<>"",D30<>""),"✓","")
E31: =IF(AND(A31<>"",B31<>"",C31<>"",D31<>""),"✓","")
E32: =IF(AND(A32<>"",B32<>"",C32<>"",D32<>""),"✓","")
... E50: =IF(AND(A50<>"",B50<>"",C50<>"",D50<>""),"✓","")
A52: Ready to Calculate: | B52: =IF(COUNTIF(E17:E50,"✓")>0,"YES - Go to Shipment Calculation tab","NO - Complete part details")
A54: NEW PROCESS: 1. Enter customs entry number, vessel, date 2. Enter total duty from CBP Box 37 3. Enter freight invoice total (ALL charges) 4. Enter shipment weight (KGS) and skid count 5. Paste or type part details (Part #, Net Weight, QTY, Skids) 6. Go to Shipment Calculation tab - review auto-calculated costs 7. Go to ERP Upload tab - copy table and paste into ERP system 8. Record in Historical Log for future reference

Sheet Shipment Calculation
A1: AUTO-POPULATED FROM IMPORT DATA ENTRY - DO NOT EDIT
A3: Part # | B3: Net Weight(KG) | C3: QTY(M) | D3: Total Weight(KGS) | E3: # of Skids | F3: Weight % | G3: Cost Allocated | H3: Cost/KGS | I3: Cost/M
A5: =IFERROR(INDEX('Import Data Entry'!$A$17:$A$50,1),"") | B5: =IFERROR(INDEX('Import Data Entry'!$B$17:$B$50,1),"") | C5: =IFERROR(INDEX('Import Data Entry'!$C$17:$C$50,1),"") | D5: =IF(B5="","",B5*C5) | E5: =IFERROR(INDEX('Import Data Entry'!$D$17:$D$50,1),"") | F5: =IF(D5="","",D5/$D$41) | G5: =IF(F5="","",F5*$B$44) | H5: =IF(D5="","",G5/D5) | I5: =IF(C5="","",G5/C5)
A6: =IFERROR(INDEX('Import Data Entry'!$A$17:$A$50,2),"") | B6: =IFERROR(INDEX('Import Data Entry'!$B$17:$B$50,2),"") | C6: =IFERROR(INDEX('Import Data Entry'!$C$17:$C$50,2),"") | D6: =IF(B6="","",B6*C6) | E6: =IFERROR(INDEX('Import Data Entry'!$D$17:$D$50,2),"") | F6: =IF(D6="","",D6/$D$41) | G6: =IF(F6="","",F6*$B$44) | H6: =IF(D6="","",G6/D6) | I6: =IF(C6="","",G6/C6)
A7: =IFERROR(INDEX('Import Data Entry'!$A$17:$A$50,3),"") | B7: =IFERROR(INDEX('Import Data Entry'!$B$17:$B$50,3),"") | C7: =IFERROR(INDEX('Import Data Entry'!$C$17:$C$50,3),"") | D7: =IF(B7="","",B7*C7) | E7: =IFERROR(INDEX('Import Data Entry'!$D$17:$D$50,3),"") | F7: =IF(D7="","",D7/$D$41) | G7: =IF(F7="","",F7*$B$44) | H7: =IF(D7="","",G7/D7) | I7: =IF(C7="","",G7/C7)
A8: =IFERROR(INDEX('Import Data Entry'!$A$17:$A$50,4),"") | B8: =IFERROR(INDEX('Import Data Entry'!$B$17:$B$50,4),"") | C8: =IFERROR(INDEX('Import Data Entry'!$C$17:$C$50,4),"") | D8: =IF(B8="","",B8*C8) | E8: =IFERROR(INDEX('Import Data Entry'!$D$17:$D$50,4),"") | F8: =IF(D8="","",D8/$D$41) | G8: =IF(F8="","",F8*$B$44) | H8: =IF(D8="","",G8/D8) | I8: =IF(C8="","",G8/C8)
A9: =IFERROR(INDEX('Import Data Entry'!$A$17:$A$50,5),"") | B9: =IFERROR(INDEX('Import Data Entry'!$B$17:$B$50,5),"") | C9: =IFERROR(INDEX('Import Data Entry'!$C$17:$C$50,5),"") | D9: =IF(B9="","",B9*C9) | E9: =IFERROR(INDEX('Import Data Entry'!$D$17:$D$50,5),"") | F9: =IF(D9="","",D9/$D$41) | G9: =IF(F9="","",F9*$B$44) | H9: =IF(D9="","",G9/D9) | I9: =IF(C9="","",G9/C9)
A10: =IFERROR(INDEX('Import Data Entry'!$A$17:$A$50,6),"") | B10: =IFERROR(INDEX('Import Data Entry'!$B$17:$B$50,6),"") | C10: =IFERROR(INDEX('Import Data Entry'!$C$17:$C$50,6),"") | D10: =IF(B10="","",B10*C10) | E10: =IFERROR(INDEX('Import Data Entry'!$D$17:$D$50,6),"") | F10: =IF(D10="","",D10/$D$41) | G10: =IF(F10="","",F10*$B$44) | H10: =IF(D10="","",G10/D10) | I10: =IF(C10="","",G10/C10)
A11: =IFERROR(INDEX('Import Data Entry'!$A$17:$A$50,7),"") | B11: =IFERROR(INDEX('Import Data Entry'!$B$17:$B$50,7),"") | C11: =IFERROR(INDEX('Import Data Entry'!$C$17:$C$50,7),"") | D11: =IF(B11="","",B11*C11) | E11: =IFERROR(INDEX('Import Data Entry'!$D$17:$D$50,7),"") | F11: =IF(D11="","",D11/$D$41) | G11: =IF(F11="","",F11*$B$44) | H11: =IF(D11="","",G11/D11) | I11: =IF(C11="","",G11/C11)
A12: =IFERROR(INDEX('Import Data Entry'!$A$17:$A$50,8),"") | B12: =IFERROR(INDEX('Import Data Entry'!$B$17:$B$50,8),"") | C12: =IFERROR(INDEX('Import Data Entry'!$C$17:$C$50,8),"") | D12: =IF(B12="","",B12*C12) | E12: =IFERROR(INDEX('Import Data Entry'!$D$17:$D$50,8),"") | F12: =IF(D12="","",D12/$D$41) | G12: =IF(F12="","",F12*$B$44) | H12: =IF(D12="","",G12/D12) | I12: =IF(C12="","",G12/C12)
A13: =IFERROR(INDEX('Import Data Entry'!$A$17:$A$50,9),"") | B13: =IFERROR(INDEX('Import Data Entry'!$B$17:$B$50,9),"") | C13: =IFERROR(INDEX('Import Data Entry'!$C$17:$C$50,9),"") | D13: =IF(B13="","",B13*C13) | E13: =IFERROR(INDEX('Import Data Entry'!$D$17:$D$50,9),"") | F13: =IF(D13="","",D13/$D$41) | G13: =IF(F13="","",F13*$B$44) | H13: =IF(D13="","",G13/D13) | I13: =IF(C13="","",G13/C13)
A14: =IFERROR(INDEX('Import Data Entry'!$A$17:$A$50,10),"") | B14: =IFERROR(INDEX('Import Data Entry'!$B$17:$B$50,10),"") | C14: =IFERROR(INDEX('Import Data Entry'!$C$17:$C$50,10),"") | D14: =IF(B14="","",B14*C14) | E14: =IFERROR(INDEX('Import Data Entry'!$D$17:$D$50,10),"") | F14: =IF(D14="","",D14/$D$41) | G14: =IF(F14="","",F14*$B$44) | H14: =IF(D14="","",G14/D14) | I14: =IF(C14="","",G14/C14)
A15: =IFERROR(INDEX('Import Data Entry'!$A$17:$A$50,11),"") | B15: =IFERROR(INDEX('Import Data Entry'!$B$17:$B$50,11),"") | C15: =IFERROR(INDEX('Import Data Entry'!$C$17:$C$50,11),"") | D15: =IF(B15="","",B15*C15) | E15: =IFERROR(INDEX('Import Data Entry'!$D$17:$D$50,11),"") | F15: =IF(D15="","",D15/$D$41) | G15: =IF(F15="","",F15*$B$44) | H15: =IF(D15="","",G15/D15) | I15: =IF(C15="","",G15/C15)
A16: =IFERROR(INDEX('Import Data Entry'!$A$17:$A$50,12),"") | B16: =IFERROR(INDEX('Import Data Entry'!$B$17:$B$50,12),"") | C16: =IFERROR(INDEX('Import Data Entry'!$C$17:$C$50,12),"") | D16: =IF(B16="","",B16*C16) | E16: =IFERROR(INDEX('Import Data Entry'!$D$17:$D$50,12),"") | F16: =IF(D16="","",D16/$D$41) | G16: =IF(F16="","",F16*$B$44) | H16: =IF(D16="","",G16/D16) | I16: =IF(C16="","",G16/C16)
A17: =IFERROR(INDEX('Import Data Entry'!$A$17:$A$50,13),"") | B17: =IFERROR(INDEX('Import Data Entry'!$B$17:$B$50,13),"") | C17: =IFERROR(INDEX('Import Data Entry'!$C$17:$C$50,13),"") | D17: =IF(B17="","",B17*C17) | E17: =IFERROR(INDEX('Import Data Entry'!$D$17:$D$50,13),"") | F17: =IF(D17="","",D17/$D$41) | G17: =IF(F17="","",F17*$B$44) | H17: =IF(D17="","",G17/D17) | I17: =IF(C17="","",G17/C17)
A18: =IFERROR(INDEX('Import Data Entry'!$A$17:$A$50,14),"") | B18: =IFERROR(INDEX('Import Data Entry'!$B$17:$B$50,14),"") | C18: =IFERROR(INDEX('Import Data Entry'!$C$17:$C$50,14),"") | D18: =IF(B18="","",B18*C18) | E18: =IFERROR(INDEX('Import Data Entry'!$D$17:$D$50,14),"") | F18: =IF(D18="","",D18/$D$41) | G18: =IF(F18="","",F18*$B$44) | H18: =IF(D18="","",G18/D18) | I18: =IF(C18="","",G18/C18)
A19: =IFERROR(INDEX('Import Data Entry'!$A$17:$A$50,15),"") | B19: =IFERROR(INDEX('Import Data Entry'!$B$17:$B$50,15),"") | C19: =IFERROR(INDEX('Import Data Entry'!$C$17:$C$50,15),"") | D19: =IF(B19="","",B19*C19) | E19: =IFERROR(INDEX('Import Data Entry'!$D$17:$D$50,15),"") | F19: =IF(D19="","",D19/$D$41) | G19: =IF(F19="","",F19*$B$44) | H19: =IF(D19="","",G19/D19) | I19: =IF(C19="","",G19/C19)
A20: =IFERROR(INDEX('Import Data Entry'!$A$17:$A$50,16),"") | B20: =IFERROR(INDEX('Import Data Entry'!$B$17:$B$50,16),"") | C20: =IFERROR(INDEX('Import Data Entry'!$C$17:$C$50,16),"") | D20: =IF(B20="","",B20*C20) | E20: =IFERROR(INDEX('Import Data Entry'!$D$17:$D$50,16),"") | F20: =IF(D20="","",D20/$D$41) | G20: =IF(F20="","",F20*$B$44) | H20: =IF(D20="","",G20/D20) | I20: =IF(C20="","",G20/C20)
A21: =IFERROR(INDEX('Import Data Entry'!$A$17:$A$50,17),"") | B21: =IFERROR(INDEX('Import Data Entry'!$B$17:$B$50,17),"") | C21: =IFERROR(INDEX('Import Data Entry'!$C$17:$C$50,17),"") | D21: =IF(B21="","",B21*C21) | E21: =IFERROR(INDEX('Import Data Entry'!$D$17:$D$50,17),"") | F21: =IF(D21="","",D21/$D$41) | G21: =IF(F21="","",F21*$B$44) | H21: =IF(D21="","",G21/D21) | I21: =IF(C21="","",G21/C21)
A22: =IFERROR(INDEX('Import Data Entry'!$A$17:$A$50,18),"") | B22: =IFERROR(INDEX('Import Data Entry'!$B$17:$B$50,18),"") | C22: =IFERROR(INDEX('Import Data Entry'!$C$17:$C$50,18),"") | D22: =IF(B22="","",B22*C22) | E22: =IFERROR(INDEX('Import Data Entry'!$D$17:$D$50,18),"") | F22: =IF(D22="","",D22/$D$41) | G22: =IF(F22="","",F22*$B$44) | H22: =IF(D22="","",G22/D22) | I22: =IF(C22="","",G22/C22)
A23: =IFERROR(INDEX('Import Data Entry'!$A$17:$A$50,19),"") | B23: =IFERROR(INDEX('Import Data Entry'!$B$17:$B$50,19),"") | C23: =IFERROR(INDEX('Import Data Entry'!$C$17:$C$50,19),"") | D23: =IF(B23="","",B23*C23) | E23: =IFERROR(INDEX('Import Data Entry'!$D$17:$D$50,19),"") | F23: =IF(D23="","",D23/$D$41) | G23: =IF(F23="","",F23*$B$44) | H23: =IF(D23="","",G23/D23) | I23: =IF(C23="","",G23/C23)
A24: =IFERROR(INDEX('Import Data Entry'!$A$17:$A$50,20),"") | B24: =IFERROR(INDEX('Import Data Entry'!$B$17:$B$50,20),"") | C24: =IFERROR(INDEX('Import Data Entry'!$C$17:$C$50,20),"") | D24: =IF(B24="","",B24*C24) | E24: =IFERROR(INDEX('Import Data Entry'!$D$17:$D$50,20),"") | F24: =IF(D24="","",D24/$D$41) | G24: =IF(F24="","",F24*$B$44) | H24: =IF(D24="","",G24/D24) | I24: =IF(C24="","",G24/C24)
A25: =IFERROR(INDEX('Import Data Entry'!$A$17:$A$50,21),"") | B25: =IFERROR(INDEX('Import Data Entry'!$B$17:$B$50,21),"") | C25: =IFERROR(INDEX('Import Data Entry'!$C$17:$C$50,21),"") | D25: =IF(B25="","",B25*C25) | E25: =IFERROR(INDEX('Import Data Entry'!$D$17:$D$50,21),"") | F25: =IF(D25="","",D25/$D$41) | G25: =IF(F25="","",F25*$B$44) | H25: =IF(D25="","",G25/D25) | I25: =IF(C25="","",G25/C25)
A26: =IFERROR(INDEX('Import Data Entry'!$A$17:$A$50,22),"") | B26: =IFERROR(INDEX('Import Data Entry'!$B$17:$B$50,22),"") | C26: =IFERROR(INDEX('Import Data Entry'!$C$17:$C$50,22),"") | D26: =IF(B26="","",B26*C26) | E26: =IFERROR(INDEX('Import Data Entry'!$D$17:$D$50,22),"") | F26: =IF(D26="","",D26/$D$41) | G26: =IF(F26="","",F26*$B$44) | H26: =IF(D26="","",G26/D26) | I26: =IF(C26="","",G26/C26)
A27: =IFERROR(INDEX('Import Data Entry'!$A$17:$A$50,23),"") | B27: =IFERROR(INDEX('Import Data Entry'!$B$17:$B$50,23),"") | C27: =IFERROR(INDEX('Import Data Entry'!$C$17:$C$50,23),"") | D27: =IF(B27="","",B27*C27) | E27: =IFERROR(INDEX('Import Data Entry'!$D$17:$D$50,23),"") | F27: =IF(D27="","",D27/$D$41) | G27: =IF(F27="","",F27*$B$44) | H27: =IF(D27="","",G27/D27) | I27: =IF(C27="","",G27/C27)
A28: =IFERROR(INDEX('Import Data Entry'!$A$17:$A$50,24),"") | B28: =IFERROR(INDEX('Import Data Entry'!$B$17:$B$50,24),"") | C28: =IFERROR(INDEX('Import Data Entry'!$C$17:$C$50,24),"") | D28: =IF(B28="","",B28*C28) | E28: =IFERROR(INDEX('Import Data Entry'!$D$17:$D$50,24),"") | F28: =IF(D28="","",D28/$D$41) | G28: =IF(F28="","",F28*$B$44) | H28: =IF(D28="","",G28/D28) | I28: =IF(C28="","",G28/C28)
A29: =IFERROR(INDEX('Import Data Entry'!$A$17:$A$50,25),"") | B29: =IFERROR(INDEX('Import Data Entry'!$B$17:$B$50,25),"") | C29: =IFERROR(INDEX('Import Data Entry'!$C$17:$C$50,25),"") | D29: =IF(B29="","",B29*C29) | E29: =IFERROR(INDEX('Import Data Entry'!$D$17:$D$50,25),"") | F29: =IF(D29="","",D29/$D$41) | G29: =IF(F29="","",F29*$B$44) | H29: =IF(D29="","",G29/D29) | I29: =IF(C29="","",G29/C29)
A30: =IFERROR(INDEX('Import Data Entry'!$A$17:$A$50,26),"") | B30: =IFERROR(INDEX('Import Data Entry'!$B$17:$B$50,26),"") | C30: =IFERROR(INDEX('Import Data Entry'!$C$17:$C$50,26),"") | D30: =IF(B30="","",B30*C30) | E30: =IFERROR(INDEX('Import Data Entry'!$D$17:$D$50,26),"") | F30: =IF(D30="","",D30/$D$41) | G30: =IF(F30="","",F30*$B$44) | H30: =IF(D30="","",G30/D30) | I30: =IF(C30="","",G30/C30)
A31: =IFERROR(INDEX('Import Data Entry'!$A$17:$A$50,27),"") | B31: =IFERROR(INDEX('Import Data Entry'!$B$17:$B$50,27),"") | C31: =IFERROR(INDEX('Import Data Entry'!$C$17:$C$50,27),"") | D31: =IF(B31="","",B31*C31) | E31: =IFERROR(INDEX('Import Data Entry'!$D$17:$D$50,27),"") | F31: =IF(D31="","",D31/$D$41) | G31: =IF(F31="","",F31*$B$44) | H31: =IF(D31="","",G31/D31) | I31: =IF(C31="","",G31/C31)
A32: =IFERROR(INDEX('Import Data Entry'!$A$17:$A$50,28),"") | B32: =IFERROR(INDEX('Import Data Entry'!$B$17:$B$50,28),"") | C32: =IFERROR(INDEX('Import Data Entry'!$C$17:$C$50,28),"") | D32: =IF(B32="","",B32*C32) | E32: =IFERROR(INDEX('Import Data Entry'!$D$17:$D$50,28),"") | F32: =IF(D32="","",D32/$D$41) | G32: =IF(F32="","",F32*$B$44) | H32: =IF(D32="","",G32/D32) | I32: =IF(C32="","",G32/C32)
A33: =IFERROR(INDEX('Import Data Entry'!$A$17:$A$50,29),"") | B33: =IFERROR(INDEX('Import Data Entry'!$B$17:$B$50,29),"") | C33: =IFERROR(INDEX('Import Data Entry'!$C$17:$C$50,29),"") | D33: =IF(B33="","",B33*C33) | E33: =IFERROR(INDEX('Import Data Entry'!$D$17:$D$50,29),"") | F33: =IF(D33="","",D33/$D$41) | G33: =IF(F33="","",F33*$B$44) | H33: =IF(D33="","",G33/D33) | I33: =IF(C33="","",G33/C33)
A34: =IFERROR(INDEX('Import Data Entry'!$A$17:$A$50,30),"") | B34: =IFERROR(INDEX('Import Data Entry'!$B$17:$B$50,30),"") | C34: =IFERROR(INDEX('Import Data Entry'!$C$17:$C$50,30),"") | D34: =IF(B34="","",B34*C34) | E34: =IFERROR(INDEX('Import Data Entry'!$D$17:$D$50,30),"") | F34: =IF(D34="","",D34/$D$41) | G34: =IF(F34="","",F34*$B$44) | H34: =IF(D34="","",G34/D34) | I34: =IF(C34="","",G34/C34)
A35: =IFERROR(INDEX('Import Data Entry'!$A$17:$A$50,31),"") | B35: =IFERROR(INDEX('Import Data Entry'!$B$17:$B$50,31),"") | C35: =IFERROR(INDEX('Import Data Entry'!$C$17:$C$50,31),"") | D35: =IF(B35="","",B35*C35) | E35: =IFERROR(INDEX('Import Data Entry'!$D$17:$D$50,31),"") | F35: =IF(D35="","",D35/$D$41) | G35: =IF(F35="","",F35*$B$44) | H35: =IF(D35="","",G35/D35) | I35: =IF(C35="","",G35/C35)
A36: =IFERROR(INDEX('Import Data Entry'!$A$17:$A$50,32),"") | B36: =IFERROR(INDEX('Import Data Entry'!$B$17:$B$50,32),"") | C36: =IFERROR(INDEX('Import Data Entry'!$C$17:$C$50,32),"") | D36: =IF(B36="","",B36*C36) | E36: =IFERROR(INDEX('Import Data Entry'!$D$17:$D$50,32),"") | F36: =IF(D36="","",D36/$D$41) | G36: =IF(F36="","",F36*$B$44) | H36: =IF(D36="","",G36/D36) | I36: =IF(C36="","",G36/C36)
A37: =IFERROR(INDEX('Import Data Entry'!$A$17:$A$50,33),"") | B37: =IFERROR(INDEX('Import Data Entry'!$B$17:$B$50,33),"") | C37: =IFERROR(INDEX('Import Data Entry'!$C$17:$C$50,33),"") | D37: =IF(B37="","",B37*C37) | E37: =IFERROR(INDEX('Import Data Entry'!$D$17:$D$50,33),"") | F37: =IF(D37="","",D37/$D$41) | G37: =IF(F37="","",F37*$B$44) | H37: =IF(D37="","",G37/D37) | I37: =IF(C37="","",G37/C37)
A38: =IFERROR(INDEX('Import Data Entry'!$A$17:$A$50,34),"") | B38: =IFERROR(INDEX('Import Data Entry'!$B$17:$B$50,34),"") | C38: =IFERROR(INDEX('Import Data Entry'!$C$17:$C$50,34),"") | D38: =IF(B38="","",B38*C38) | E38: =IFERROR(INDEX('Import Data Entry'!$D$17:$D$50,34),"") | F38: =IF(D38="","",D38/$D$41) | G38: =IF(F38="","",F38*$B$44) | H38: =IF(D38="","",G38/D38) | I38: =IF(C38="","",G38/C38)
A39: =IFERROR(INDEX('Import Data Entry'!$A$17:$A$50,35),"") | B39: =IFERROR(INDEX('Import Data Entry'!$B$17:$B$50,35),"") | C39: =IFERROR(INDEX('Import Data Entry'!$C$17:$C$50,35),"") | D39: =IF(B39="","",B39*C39) | E39: =IFERROR(INDEX('Import Data Entry'!$D$17:$D$50,35),"") | F39: =IF(D39="","",D39/$D$41) | G39: =IF(F39="","",F39*$B$44) | H39: =IF(D39="","",G39/D39) | I39: =IF(C39="","",G39/C39)
A41: Totals | C41: =SUM(C5:C39) | D41: =SUM(D5:D39) | E41: =SUM(E5:E39) | G41: =SUM(G5:G39)
A42: Totals
A44: Shipment cost | B44: ='Import Data Entry'!B13 | C44: Total # of Skids: | D44: ='Import Data Entry'!B11
...

Sheet Historical Log
A1: Part # | B1: Freight Cost/M | C1: Date | D1: Net Weight
A2: → To add current shipment data, copy Cost/M values from Shipment Calculation tab and paste below

Sheet ERP Upload Template
A1: ERP IMPORT - COPY TO CLIPBOARD
A2: Part_Number | B2: DRM_Code | C2: Freight_Cost_Per_M | D2: Entry_Date | E2: Vessel
A3: ='Shipment Calculation'!A5 | B3: 18735 | C3: ='Shipment Calculation'!I5 | D3: ='Import Data Entry'!B6 | E3: ='Import Data Entry'!B5
A4: ='Shipment Calculation'!A6 | B4: 18732 | C4: ='Shipment Calculation'!I6 | D4: ='Import Data Entry'!B6 | E4: ='Import Data Entry'!B5
A5: ='Shipment Calculation'!A7 | B5: 18736 | C5: ='Shipment Calculation'!I7 | D5: ='Import Data Entry'!B6 | E5: ='Import Data Entry'!B5
A6: ='Shipment Calculation'!A8 | B6: 18734 | C6: ='Shipment Calculation'!I8 | D6: ='Import Data Entry'!B6 | E6: ='Import Data Entry'!B5
A7: ='Shipment Calculation'!A9 | C7: ='Shipment Calculation'!I9 | D7: ='Import Data Entry'!B6 | E7: ='Import Data Entry'!B5
A8: ='Shipment Calculation'!A10 | C8: ='Shipment Calculation'!I10 | D8: ='Import Data Entry'!B6 | E8: ='Import Data Entry'!B5
A9: ='Shipment Calculation'!A11 | C9: ='Shipment Calculation'!I11 | D9: ='Import Data Entry'!B6 | E9: ='Import Data Entry'!B5
A10: ='Shipment Calculation'!A12 | C10: ='Shipment Calculation'!I12 | D10: ='Import Data Entry'!B6 | E10: ='Import Data Entry'!B5
A11: ='Shipment Calculation'!A13 | C11: ='Shipment Calculation'!I13 | D11: ='Import Data Entry'!B6 | E11: ='Import Data Entry'!B5
A12: ='Shipment Calculation'!A14 | C12: ='Shipment Calculation'!I14 | D12: ='Import Data Entry'!B6 | E12: ='Import Data Entry'!B5
A13: ='Shipment Calculation'!A15 | C13: ='Shipment Calculation'!I15 | D13: ='Import Data Entry'!B6 | E13: ='Import Data Entry'!B5
A14: ='Shipment Calculation'!A16 | C14: ='Shipment Calculation'!I16 | D14: ='Import Data Entry'!B6 | E14: ='Import Data Entry'!B5
A15: ='Shipment Calculation'!A17 | C15: ='Shipment Calculation'!I17 | D15: ='Import Data Entry'!B6 | E15: ='Import Data Entry'!B5
A16: ='Shipment Calculation'!A18 | C16: ='Shipment Calculation'!I18 | D16: ='Import Data Entry'!B6 | E16: ='Import Data Entry'!B5
A17: ='Shipment Calculation'!A19 | C17: ='Shipment Calculation'!I19 | D17: ='Import Data Entry'!B6 | E17: ='Import Data Entry'!B5
A18: ='Shipment Calculation'!A20 | C18: ='Shipment Calculation'!I20 | D18: ='Import Data Entry'!B6 | E18: ='Import Data Entry'!B5
A19: ='Shipment Calculation'!A21 | C19: ='Shipment Calculation'!I21 | D19: ='Import Data Entry'!B6 | E19: ='Import Data Entry'!B5
A20: ='Shipment Calculation'!A22 | C20: ='Shipment Calculation'!I22 | D20: ='Import Data Entry'!B6 | E20: ='Import Data Entry'!B5
A21: ='Shipment Calculation'!A23 | C21: ='Shipment Calculation'!I23 | D21: ='Import Data Entry'!B6 | E21: ='Import Data Entry'!B5
A22: ='Shipment Calculation'!A24 | C22: ='Shipment Calculation'!I24 | D22: ='Import Data Entry'!B6 | E22: ='Import Data Entry'!B5
A23: ='Shipment Calculation'!A25 | C23: ='Shipment Calculation'!I25 | D23: ='Import Data Entry'!B6 | E23: ='Import Data Entry'!B5
A24: ='Shipment Calculation'!A26 | C24: ='Shipment Calculation'!I26 | D24: ='Import Data Entry'!B6 | E24: ='Import Data Entry'!B5
A25: ='Shipment Calculation'!A27 | C25: ='Shipment Calculation'!I27 | D25: ='Import Data Entry'!B6 | E25: ='Import Data Entry'!B5
A26: ='Shipment Calculation'!A28 | C26: ='Shipment Calculation'!I28 | D26: ='Import Data Entry'!B6 | E26: ='Import Data Entry'!B5
A27: ='Shipment Calculation'!A29 | C27: ='Shipment Calculation'!I29 | D27: ='Import Data Entry'!B6 | E27: ='Import Data Entry'!B5
A28: ='Shipment Calculation'!A30 | C28: ='Shipment Calculation'!I30 | D28: ='Import Data Entry'!B6 | E28: ='Import Data Entry'!B5
A29: ='Shipment Calculation'!A31 | C29: ='Shipment Calculation'!I31 | D29: ='Import Data Entry'!B6 | E29: ='Import Data Entry'!B5
A30: ='Shipment Calculation'!A32 | C30: ='Shipment Calculation'!I32 | D30: ='Import Data Entry'!B6 | E30: ='Import Data Entry'!B5
A31: ='Shipment Calculation'!A33 | C31: ='Shipment Calculation'!I33 | D31: ='Import Data Entry'!B6 | E31: ='Import Data Entry'!B5
A32: ='Shipment Calculation'!A34 | C32: ='Shipment Calculation'!I34 | D32: ='Import Data Entry'!B6 | E32: ='Import Data Entry'!B5
A33: ='Shipment Calculation'!A35 | C33: ='Shipment Calculation'!I35 | D33: ='Import Data Entry'!B6 | E33: ='Import Data Entry'!B5
A34: ='Shipment Calculation'!A36 | C34: ='Shipment Calculation'!I36 | D34: ='Import Data Entry'!B6 | E34: ='Import Data Entry'!B5
A35: ='Shipment Calculation'!A37 | C35: ='Shipment Calculation'!I37 | D35: ='Import Data Entry'!B6 | E35: ='Import Data Entry'!B5
A36: ='Shipment Calculation'!A38 | C36: ='Shipment Calculation'!I38 | D36: ='Import Data Entry'!B6 | E36: ='Import Data Entry'!B5
A37: ='Shipment Calculation'!A39 | C37: ='Shipment Calculation'!I39 | D37: ='Import Data Entry'!B6 | E37: ='Import Data Entry'!B5

Sheet Sheet2
A1: Date Reference Matrix
A2: Part # | B2: Cost History
